Workbook

Sheet README
A1: BANK STATEMENT & RECONCILIATION DATASET - FY 2025
A2: Project: Transaction Classification & Reconciliation Solution for Businesses
A4: IMPORTANT: ALL DATA IS FICTIONAL. Company, bank, account number, people and amounts are invented for study and testing only.
A6: Company profile
A7: Name: Lagosmart Distribution Ltd (fictional) | Business: wholesale & retail distribution of packaged goods, Lagos
A8: Bank: Sample Commercial Bank Plc (fictional) | Account: Current Account, NGN, No. 0123456789 (fictional)
A9: Period: 1 January 2025 - 31 December 2025 | Opening balance: N12,500,000.00 (assumed reconciled at 1 Jan 2025)
A11: Sheets
A12: 1. Bank Statement - what the bank shows (the raw input to your classifier). Running balance is a formula.
A13: 2. Cash Book - the company's own ledger of cash (the second input to your reconciliation engine).
A14: 3. Answer Key - ground-truth category, FS class, clarity flag and reconciliation status for every bank line. Use it to train / score your classifier.
A15: 4. Recon Exceptions - every reconciling item between bank and cash book, with its effect on the adjusted balance.
... A34: - Weekends/public holidays are not modelled in detail; posting dates fall on business days.

Sheet Bank Statement
A1: SAMPLE COMMERCIAL BANK PLC
A2: STATEMENT OF ACCOUNT (FICTIONAL - FOR STUDY USE ONLY)
A3: Account Name | C3: LAGOSMART DISTRIBUTION LTD | F3: Opening Balance | H3: 12500000
A4: Account Number | C4: 0123456789 | F4: Closing Balance | H4: =H581 -> 1.1181209e+08
A5: Account Type / Currency | C5: CURRENT / NGN
A6: Statement Period | C6: 01-Jan-2025 to 31-Dec-2025
A8: S/N | B8: Trans Date | C8: Value Date | D8: Reference | E8: Narration | F8: Debit (NGN) | G8: Credit (NGN) | H8: Balance (NGN)
A9: 1 | B9: 45659 | C9: 45659 | D9: NIP250102268377 | E9: NIP TRF FROM DELTA FRESH MART/INV 1051 | G9: 2086200 | H9: =$H$3+G9-F9 -> 14586200
A10: 2 | B10: 45663 | C10: 45664 | D10: NIP250106836615 | E10: NIP TRF FROM KANO WHOLESALE HUB/INV 1049 | G10: 3096700 | H10: =H9+G10-F10 -> 17682900
A11: 3 | B11: 45663 | C11: 45663 | D11: NIP250106512077 | E11: NIP TRF FROM BRIGHTWAY SCHOOLS/INV 1067 | G11: 2234000 | H11: =H10+G11-F11 -> 19916900
A12: 4 | B12: 45663 | C12: 45663 | D12: NIP250106917411 | E12: NIP TRF FROM DELTA FRESH MART/INV 1068 | G12: 3586300 | H12: =H11+G12-F12 -> 23503200
A13: 5 | B13: 45663 | C13: 45663 | D13: POS250106543421 | E13: POS SETTLEMENT MID 20517028 0601 | G13: 1564104.2 | H13: =H12+G13-F13 -> 25067304
A14: 6 | B14: 45663 | C14: 45663 | D14: FT250106618382 | E14: BROADBAND SUBSCRIPTION INV 64894 | F14: 85000 | H14: =H13+G14-F14 -> 24982304
A15: 7 | B15: 45663 | C15: 45663 | D15: NIP250106827822 | E15: NIP TRF TO ADELEKE PROPERTIES LTD/RENT WAREHOUSE 2025 | F15: 7200000 | H15: =H14+G15-F15 -> 17782304
A16: 8 | B16: 45665 | C16: 45666 | D16: NIP250108413860 | E16: NIP TRF FROM GREENFIELD STORES LTD/INV 1079 | G16: 1486100 | H16: =H15+G16-F16 -> 19268404
A17: 9 | B17: 45665 | C17: 45665 | D17: NIP250108593382 | E17: NIP TRF TO LEKKI PLAZA MGT/SHOP RENT Q1 | F17: 1500000 | H17: =H16+G17-F17 -> 17768404
A18: 10 | B18: 45666 | C18: 45666 | D18: FT250109030935 | E18: ONLINE GATEWAY SETTLEMENT BATCH 52482 | G18: 780536.26 | H18: =H17+G18-F18 -> 18548940
A19: 11 | B19: 45666 | C19: 45666 | D19: POS250109928097 | E19: POS PURCHASE - PETRO STATION 1010 IKEJA | F19: 323833.15 | H19: =H18+G19-F19 -> 18225107
A20: 12 | B20: 45667 | C20: 45667 | D20: CSH250110300757 | E20: CDM DEPOSIT 9912 | G20: 816396.53 | H20: =H19+G20-F20 -> 19041504
A21: 13 | B21: 45667 | C21: 45667 | D21: FT250110801698 | E21: LIRS PAYE REMITTANCE RRR 9603333279 DEC 2024 | F21: 450800 | H21: =H20+G21-F21 -> 18590704
A22: 14 | B22: 45670 | C22: 45670 | D22: NIP250113396098 | E22: NIP TRF FROM PRIME HOSPITALITY LTD/INV 1077 | G22: 2632600 | H22: =H21+G22-F22 -> 21223304
A23: 15 | B23: 45670 | C23: 45671 | D23: POS250113781580 | E23: POS SETTLEMENT MID 20518546 1301 | G23: 670841.79 | H23: =H22+G23-F23 -> 21894146
A24: 16 | B24: 45670 | C24: 45670 | D24: NIP250113450760 | E24: NIP TRF TO KEMI PLASTICS LTD/INV 4403 | F24: 1160500 | H24: =H23+G24-F24 -> 20733646
A25: 17 | B25: 45670 | C25: 45670 | D25: NIP250113056806 | E25: NIP TRF TO KEMI PLASTICS LTD/INV 4421 | F25: 1951500 | H25: =H24+G25-F25 -> 18782146
A26: 18 | B26: 45670 | C26: 45670 | D26: POS250113519505 | E26: POS PURCHASE - PETRO STATION 1743 IKEJA | F26: 284264.14 | H26: =H25+G26-F26 -> 18497882
A27: 19 | B27: 45670 | C27: 45670 | D27: POS250113672851 | E27: POS PURCHASE - OFFICE STATIONERY 414 | F27: 199288.34 | H27: =H26+G27-F27 -> 18298593
A28: 20 | B28: 45671 | C28: 45671 | D28: NIP250114709626 | E28: NIP TRF FROM DELTA FRESH MART/INV 1058 | G28: 2195200 | H28: =H27+G28-F28 -> 20493793
A29: 21 | B29: 45671 | C29: 45671 | D29: NIP250114565827 | E29: NIP TRF TO PINNACLE PACKAGING LTD/INV 4406 | F29: 969100 | H29: =H28+G29-F29 -> 19524693
A30: 22 | B30: 45671 | C30: 45671 | D30: NIP250114248265 | E30: NIP TRF TO UNITY CHEMICALS LTD/INV 4412 | F30: 2830300 | H30: =H29+G30-F30 -> 16694393
A31: 23 | B31: 45671 | C31: 45671 | D31: POS250114207091 | E31: INTL POS - SOCIAL MEDIA ADS USD 135 | F31: 209769.68 | H31: =H30+G31-F31 -> 16484624
A32: 24 | B32: 45672 | C32: 45672 | D32: CSH250115424772 | E32: CDM DEPOSIT 8071 | G32: 1335545 | H32: =H31+G32-F32 -> 17820168
A33: 25 | B33: 45672 | C33: 45673 | D33: FT250115753949 | E33: PFA PENSION CONTRIBUTION DEC 2024 BULK | F33: 828000 | H33: =H32+G33-F33 -> 16992168
A34: 26 | B34: 45677 | C34: 45677 | D34: POS250120005353 | E34: POS SETTLEMENT MID 20518254 2001 | G34: 1539349.6 | H34: =H33+G34-F34 -> 18531518
A35: 27 | B35: 45677 | C35: 45678 | D35: NIP250120242135 | E35: NIP TRF TO ZENITH CRATES & PALLETS/INV 4407 | F35: 1415000 | H35: =H34+G35-F35 -> 17116518
A36: 28 | B36: 45677 | C36: 45678 | D36: NIP250120226551 | E36: NIP TRF TO PINNACLE PACKAGING LTD/INV 4416 | F36: 2041200 | H36: =H35+G36-F36 -> 15075318
A37: 29 | B37: 45677 | C37: 45677 | D37: FT250120353512 | E37: POWER DISCO PREPAID VEND MTR 4521256 | F37: 237700 | H37: =H36+G37-F37 -> 14837618
A38: 30 | B38: 45677 | C38: 45677 | D38: NIP250120850382 | E38: NIP TRF TO BRIGHTPRINT MEDIA/FLYERS 629 | F38: 232180.8 | H38: =H37+G38-F38 -> 14605437
A39: 31 | B39: 45678 | C39: 45678 | D39: CSH250121214141 | E39: CDM DEPOSIT 6427 | G39: 342680.91 | H39: =H38+G39-F39 -> 14948118
A40: 32 | B40: 45678 | C40: 45678 | D40: FT250121705372 | E40: FIRS VAT REMITTANCE RRR 2480196322 DEC 2024 | F40: 865116.28 | H40: =H39+G40-F40 -> 14083002
A41: 33 | B41: 45679 | C41: 45679 | D41: FT250122855795 | E41: FIRS WHT REMITTANCE RRR 3542552639 | F41: 185202.57 | H41: =H40+G41-F41 -> 13897799
...

Sheet Cash Book
A1: LAGOSMART DISTRIBUTION LTD - CASH BOOK (BANK ACCOUNT) 2025
A2: Company records. Compare with the bank statement.
A3: Opening balance b/f | F3: 12500000
A5: Book Ref | B5: Date | C5: Description | D5: Receipts (NGN) | E5: Payments (NGN) | F5: Balance (NGN)
A6: CB-0001 | B6: 45659 | C6: Receipt - Delta Fresh Mart Inv 1051 | D6: 2086200 | F6: =$F$3+D6-E6 -> 14586200
A7: CB-0002 | B7: 45659 | C7: Warehouse rent 2025 | E7: 7200000 | F7: =F6+D7-E7 -> 7386200
A8: CB-0003 | B8: 45660 | C8: Receipt - Brightway Schools Inv 1067 | D8: 2234000 | F8: =F7+D8-E8 -> 9620200
A9: CB-0004 | B9: 45660 | C9: Receipt - Delta Fresh Mart Inv 1068 | D9: 3586300 | F9: =F8+D9-E9 -> 13206500
A10: CB-0005 | B10: 45663 | C10: Receipt - Kano Wholesale Hub Inv 1049 | D10: 3096700 | F10: =F9+D10-E10 -> 16303200
A11: CB-0006 | B11: 45663 | C11: POS sales settlement | D11: 1564104.2 | F11: =F10+D11-E11 -> 17867304
A12: CB-0007 | B12: 45663 | C12: Internet subscription | E12: 85000 | F12: =F11+D12-E12 -> 17782304
A13: CB-0008 | B13: 45665 | C13: Receipt - Greenfield Stores Ltd Inv 1079 | D13: 1486100 | F13: =F12+D13-E13 -> 19268404
A14: CB-0009 | B14: 45665 | C14: Shop rent Q1 | E14: 1500000 | F14: =F13+D14-E14 -> 17768404
A15: CB-0010 | B15: 45666 | C15: Online sales settlement | D15: 780536.26 | F15: =F14+D15-E15 -> 18548940
A16: CB-0011 | B16: 45666 | C16: Diesel / fuel | E16: 323833.15 | F16: =F15+D16-E16 -> 18225107
A17: CB-0012 | B17: 45666 | C17: Receipt - Prime Hospitality Ltd Inv 1077 | D17: 2632600 | F17: =F16+D17-E17 -> 20857707
A18: CB-0013 | B18: 45667 | C18: Cash sales banked | D18: 816396.53 | F18: =F17+D18-E18 -> 21674104
A19: CB-0014 | B19: 45667 | C19: PAYE Dec 2024 | E19: 450800 | F19: =F18+D19-E19 -> 21223304
A20: CB-0015 | B20: 45667 | C20: Diesel / fuel | E20: 284264.14 | F20: =F19+D20-E20 -> 20939040
A21: CB-0016 | B21: 45667 | C21: Pension Dec 2024 | E21: 828000 | F21: =F20+D21-E21 -> 20111040
A22: CB-0017 | B22: 45670 | C22: POS sales settlement | D22: 670841.79 | F22: =F21+D22-E22 -> 20781882
A23: CB-0018 | B23: 45670 | C23: Payment - Kemi Plastics Ltd | E23: 1160500 | F23: =F22+D23-E23 -> 19621382
A24: CB-0019 | B24: 45670 | C24: Payment - Kemi Plastics Ltd | E24: 1951500 | F24: =F23+D24-E24 -> 17669882
A25: CB-0020 | B25: 45670 | C25: Stationery | E25: 199288.34 | F25: =F24+D25-E25 -> 17470593
A26: CB-0021 | B26: 45671 | C26: Receipt - Delta Fresh Mart Inv 1058 | D26: 2195200 | F26: =F25+D26-E26 -> 19665793
A27: CB-0022 | B27: 45671 | C27: Payment - Pinnacle Packaging Ltd | E27: 969100 | F27: =F26+D27-E27 -> 18696693
A28: CB-0023 | B28: 45671 | C28: Payment - Unity Chemicals Ltd | E28: 2830300 | F28: =F27+D28-E28 -> 15866393
A29: CB-0024 | B29: 45671 | C29: Advertising | E29: 209769.68 | F29: =F28+D29-E29 -> 15656624
A30: CB-0025 | B30: 45671 | C30: Cash sales banked | D30: 1335545 | F30: =F29+D30-E30 -> 16992168
A31: CB-0026 | B31: 45673 | C31: Electricity prepaid | E31: 237700 | F31: =F30+D31-E31 -> 16754468
A32: CB-0027 | B32: 45677 | C32: POS sales settlement | D32: 1539349.6 | F32: =F31+D32-E32 -> 18293818
A33: CB-0028 | B33: 45677 | C33: Payment - Zenith Crates & Pallets | E33: 1415000 | F33: =F32+D33-E33 -> 16878818
A34: CB-0029 | B34: 45677 | C34: Payment - Pinnacle Packaging Ltd | E34: 2041200 | F34: =F33+D34-E34 -> 14837618
A35: CB-0030 | B35: 45677 | C35: Advertising | E35: 232180.8 | F35: =F34+D35-E35 -> 14605437
A36: CB-0031 | B36: 45678 | C36: Cash sales banked | D36: 342680.91 | F36: =F35+D36-E36 -> 14948118
A37: CB-0032 | B37: 45678 | C37: VAT Dec 2024 | E37: 865116.28 | F37: =F36+D37-E37 -> 14083002
A38: CB-0033 | B38: 45678 | C38: Petty cash float | E38: 413000 | F38: =F37+D38-E38 -> 13670002
A39: CB-0034 | B39: 45679 | C39: WHT remittance | E39: 185202.57 | F39: =F38+D39-E39 -> 13484799
A40: CB-0035 | B40: 45680 | C40: Online sales settlement | D40: 615346.61 | F40: =F39+D40-E40 -> 14100146
A41: CB-0036 | B41: 45680 | C41: Diesel / fuel | E41: 255328.23 | F41: =F40+D41-E41 -> 13844818
...

Sheet Answer Key
A1: ANSWER KEY - Classification & Reconciliation Status (ground truth for each bank line)
A2: Clarity: Clear = narration identifies the nature; Unclear = missing payer/payee/purpose; Ambiguous = fits 2+ categories. Category shown is the 'most defensible' answer.
A4: S/N | B4: Date | C4: Reference | D4: Narration | E4: Debit | F4: Credit | G4: Net Cash Effect | H4: Month | I4: Category | J4: FS Class | K4: Clarity | L4: Recon Status | M4: Cash Book Ref | N4: Reasoning / Note
A5: 1 | B5: 45659 | C5: NIP250102268377 | D5: NIP TRF FROM DELTA FRESH MART/INV 1051 | F5: 2086200 | G5: =N(F5)-N(E5) -> 2086200 | H5: =MONTH(B5) -> 1 | I5: Sales - Customer Transfers | J5: Operating | K5: Clear | L5: Matched | M5: CB-0001
A6: 2 | B6: 45663 | C6: NIP250106836615 | D6: NIP TRF FROM KANO WHOLESALE HUB/INV 1049 | F6: 3096700 | G6: =N(F6)-N(E6) -> 3096700 | H6: =MONTH(B6) -> 1 | I6: Sales - Customer Transfers | J6: Operating | K6: Clear | L6: Matched | M6: CB-0005
A7: 3 | B7: 45663 | C7: NIP250106512077 | D7: NIP TRF FROM BRIGHTWAY SCHOOLS/INV 1067 | F7: 2234000 | G7: =N(F7)-N(E7) -> 2234000 | H7: =MONTH(B7) -> 1 | I7: Sales - Customer Transfers | J7: Operating | K7: Clear | L7: Matched | M7: CB-0003
A8: 4 | B8: 45663 | C8: NIP250106917411 | D8: NIP TRF FROM DELTA FRESH MART/INV 1068 | F8: 3586300 | G8: =N(F8)-N(E8) -> 3586300 | H8: =MONTH(B8) -> 1 | I8: Sales - Customer Transfers | J8: Operating | K8: Clear | L8: Matched | M8: CB-0004
A9: 5 | B9: 45663 | C9: POS250106543421 | D9: POS SETTLEMENT MID 20517028 0601 | F9: 1564104.2 | G9: =N(F9)-N(E9) -> 1564104.2 | H9: =MONTH(B9) -> 1 | I9: Sales - POS Settlements | J9: Operating | K9: Clear | L9: Matched | M9: CB-0006 | N9: Settlement is net of merchant commission (MDR); gross sales are higher than the amount credited.
A10: 6 | B10: 45663 | C10: FT250106618382 | D10: BROADBAND SUBSCRIPTION INV 64894 | E10: 85000 | G10: =N(F10)-N(E10) -> -85000 | H10: =MONTH(B10) -> 1 | I10: Utilities (Power & Internet) | J10: Operating | K10: Clear | L10: Matched | M10: CB-0007
A11: 7 | B11: 45663 | C11: NIP250106827822 | D11: NIP TRF TO ADELEKE PROPERTIES LTD/RENT WAREHOUSE 2025 | E11: 7200000 | G11: =N(F11)-N(E11) -> -7200000 | H11: =MONTH(B11) -> 1 | I11: Rent | J11: Operating | K11: Clear | L11: Matched | M11: CB-0002 | N11: Annual rent paid upfront - spans 12 months (prepayment/accrual issue for the financial statements).
A12: 8 | B12: 45665 | C12: NIP250108413860 | D12: NIP TRF FROM GREENFIELD STORES LTD/INV 1079 | F12: 1486100 | G12: =N(F12)-N(E12) -> 1486100 | H12: =MONTH(B12) -> 1 | I12: Sales - Customer Transfers | J12: Operating | K12: Clear | L12: Matched | M12: CB-0008
A13: 9 | B13: 45665 | C13: NIP250108593382 | D13: NIP TRF TO LEKKI PLAZA MGT/SHOP RENT Q1 | E13: 1500000 | G13: =N(F13)-N(E13) -> -1500000 | H13: =MONTH(B13) -> 1 | I13: Rent | J13: Operating | K13: Clear | L13: Matched | M13: CB-0009
A14: 10 | B14: 45666 | C14: FT250109030935 | D14: ONLINE GATEWAY SETTLEMENT BATCH 52482 | F14: 780536.26 | G14: =N(F14)-N(E14) -> 780536.26 | H14: =MONTH(B14) -> 1 | I14: Sales - Online Gateway Settlements | J14: Operating | K14: Clear | L14: Matched | M14: CB-0010 | N14: Net of gateway fees.
A15: 11 | B15: 45666 | C15: POS250109928097 | D15: POS PURCHASE - PETRO STATION 1010 IKEJA | E15: 323833.15 | G15: =N(F15)-N(E15) -> -323833.15 | H15: =MONTH(B15) -> 1 | I15: Fuel & Logistics | J15: Operating | K15: Clear | L15: Matched | M15: CB-0011 | N15: Could be generator diesel or vehicle fuel - same expense class, different cost centre.
A16: 12 | B16: 45667 | C16: CSH250110300757 | D16: CDM DEPOSIT 9912 | F16: 816396.53 | G16: =N(F16)-N(E16) -> 816396.53 | H16: =MONTH(B16) -> 1 | I16: Sales - Cash Deposits | J16: Operating | K16: Unclear | L16: Matched | M16: CB-0013 | N16: No payer identified. Could be daily cash sales, debtor collections or an owner top-up. Tie to daily sales/cash records.
A17: 13 | B17: 45667 | C17: FT250110801698 | D17: LIRS PAYE REMITTANCE RRR 9603333279 DEC 2024 | E17: 450800 | G17: =N(F17)-N(E17) -> -450800 | H17: =MONTH(B17) -> 1 | I17: PAYE Remittance | J17: Operating | K17: Clear | L17: Matched | M17: CB-0014
A18: 14 | B18: 45670 | C18: NIP250113396098 | D18: NIP TRF FROM PRIME HOSPITALITY LTD/INV 1077 | F18: 2632600 | G18: =N(F18)-N(E18) -> 2632600 | H18: =MONTH(B18) -> 1 | I18: Sales - Customer Transfers | J18: Operating | K18: Clear | L18: Matched | M18: CB-0012
A19: 15 | B19: 45670 | C19: POS250113781580 | D19: POS SETTLEMENT MID 20518546 1301 | F19: 670841.79 | G19: =N(F19)-N(E19) -> 670841.79 | H19: =MONTH(B19) -> 1 | I19: Sales - POS Settlements | J19: Operating | K19: Clear | L19: Matched | M19: CB-0017 | N19: Settlement is net of merchant commission (MDR); gross sales are higher than the amount credited.
A20: 16 | B20: 45670 | C20: NIP250113450760 | D20: NIP TRF TO KEMI PLASTICS LTD/INV 4403 | E20: 1160500 | G20: =N(F20)-N(E20) -> -1160500 | H20: =MONTH(B20) -> 1 | I20: Inventory / Supplier Payments | J20: Operating | K20: Clear | L20: Matched | M20: CB-0018
A21: 17 | B21: 45670 | C21: NIP250113056806 | D21: NIP TRF TO KEMI PLASTICS LTD/INV 4421 | E21: 1951500 | G21: =N(F21)-N(E21) -> -1951500 | H21: =MONTH(B21) -> 1 | I21: Inventory / Supplier Payments | J21: Operating | K21: Clear | L21: Matched | M21: CB-0019
A22: 18 | B22: 45670 | C22: POS250113519505 | D22: POS PURCHASE - PETRO STATION 1743 IKEJA | E22: 284264.14 | G22: =N(F22)-N(E22) -> -284264.14 | H22: =MONTH(B22) -> 1 | I22: Fuel & Logistics | J22: Operating | K22: Clear | L22: Matched | M22: CB-0015 | N22: Could be generator diesel or vehicle fuel - same expense class, different cost centre.
A23: 19 | B23: 45670 | C23: POS250113672851 | D23: POS PURCHASE - OFFICE STATIONERY 414 | E23: 199288.34 | G23: =N(F23)-N(E23) -> -199288.34 | H23: =MONTH(B23) -> 1 | I23: Office & Admin | J23: Operating | K23: Clear | L23: Matched | M23: CB-0020
A24: 20 | B24: 45671 | C24: NIP250114709626 | D24: NIP TRF FROM DELTA FRESH MART/INV 1058 | F24: 2195200 | G24: =N(F24)-N(E24) -> 2195200 | H24: =MONTH(B24) -> 1 | I24: Sales - Customer Transfers | J24: Operating | K24: Clear | L24: Matched | M24: CB-0021
A25: 21 | B25: 45671 | C25: NIP250114565827 | D25: NIP TRF TO PINNACLE PACKAGING LTD/INV 4406 | E25: 969100 | G25: =N(F25)-N(E25) -> -969100 | H25: =MONTH(B25) -> 1 | I25: Inventory / Supplier Payments | J25: Operating | K25: Clear | L25: Matched | M25: CB-0022
A26: 22 | B26: 45671 | C26: NIP250114248265 | D26: NIP TRF TO UNITY CHEMICALS LTD/INV 4412 | E26: 2830300 | G26: =N(F26)-N(E26) -> -2830300 | H26: =MONTH(B26) -> 1 | I26: Inventory / Supplier Payments | J26: Operating | K26: Clear | L26: Matched | M26: CB-0023
A27: 23 | B27: 45671 | C27: POS250114207091 | D27: INTL POS - SOCIAL MEDIA ADS USD 135 | E27: 209769.68 | G27: =N(F27)-N(E27) -> -209769.68 | H27: =MONTH(B27) -> 1 | I27: Marketing & Advertising | J27: Operating | K27: Clear | L27: Matched | M27: CB-0024 | N27: Foreign-currency card debits are converted at the bank rate - the Naira amount differs from the invoice.
A28: 24 | B28: 45672 | C28: CSH250115424772 | D28: CDM DEPOSIT 8071 | F28: 1335545 | G28: =N(F28)-N(E28) -> 1335545 | H28: =MONTH(B28) -> 1 | I28: Sales - Cash Deposits | J28: Operating | K28: Unclear | L28: Matched | M28: CB-0025 | N28: No payer identified. Could be daily cash sales, debtor collections or an owner top-up. Tie to daily sales/cash records.
A29: 25 | B29: 45672 | C29: FT250115753949 | D29: PFA PENSION CONTRIBUTION DEC 2024 BULK | E29: 828000 | G29: =N(F29)-N(E29) -> -828000 | H29: =MONTH(B29) -> 1 | I29: Pension Remittance | J29: Operating | K29: Clear | L29: Matched | M29: CB-0016
A30: 26 | B30: 45677 | C30: POS250120005353 | D30: POS SETTLEMENT MID 20518254 2001 | F30: 1539349.6 | G30: =N(F30)-N(E30) -> 1539349.6 | H30: =MONTH(B30) -> 1 | I30: Sales - POS Settlements | J30: Operating | K30: Clear | L30: Matched | M30: CB-0027 | N30: Settlement is net of merchant commission (MDR); gross sales are higher than the amount credited.
A31: 27 | B31: 45677 | C31: NIP250120242135 | D31: NIP TRF TO ZENITH CRATES & PALLETS/INV 4407 | E31: 1415000 | G31: =N(F31)-N(E31) -> -1415000 | H31: =MONTH(B31) -> 1 | I31: Inventory / Supplier Payments | J31: Operating | K31: Clear | L31: Matched | M31: CB-0028
A32: 28 | B32: 45677 | C32: NIP250120226551 | D32: NIP TRF TO PINNACLE PACKAGING LTD/INV 4416 | E32: 2041200 | G32: =N(F32)-N(E32) -> -2041200 | H32: =MONTH(B32) -> 1 | I32: Inventory / Supplier Payments | J32: Operating | K32: Clear | L32: Matched | M32: CB-0029
A33: 29 | B33: 45677 | C33: FT250120353512 | D33: POWER DISCO PREPAID VEND MTR 4521256 | E33: 237700 | G33: =N(F33)-N(E33) -> -237700 | H33: =MONTH(B33) -> 1 | I33: Utilities (Power & Internet) | J33: Operating | K33: Clear | L33: Matched | M33: CB-0026
A34: 30 | B34: 45677 | C34: NIP250120850382 | D34: NIP TRF TO BRIGHTPRINT MEDIA/FLYERS 629 | E34: 232180.8 | G34: =N(F34)-N(E34) -> -232180.8 | H34: =MONTH(B34) -> 1 | I34: Marketing & Advertising | J34: Operating | K34: Clear | L34: Matched | M34: CB-0030 | N34: Foreign-currency card debits are converted at the bank rate - the Naira amount differs from the invoice.
A35: 31 | B35: 45678 | C35: CSH250121214141 | D35: CDM DEPOSIT 6427 | F35: 342680.91 | G35: =N(F35)-N(E35) -> 342680.91 | H35: =MONTH(B35) -> 1 | I35: Sales - Cash Deposits | J35: Operating | K35: Unclear | L35: Matched | M35: CB-0031 | N35: No payer identified. Could be daily cash sales, debtor collections or an owner top-up. Tie to daily sales/cash records.
A36: 32 | B36: 45678 | C36: FT250121705372 | D36: FIRS VAT REMITTANCE RRR 2480196322 DEC 2024 | E36: 865116.28 | G36: =N(F36)-N(E36) -> -865116.28 | H36: =MONTH(B36) -> 1 | I36: VAT Remittance | J36: Operating | K36: Clear | L36: Matched | M36: CB-0032 | N36: Net VAT payable (output VAT less input VAT) - not equal to 7.5% of sales.
A37: 33 | B37: 45679 | C37: FT250122855795 | D37: FIRS WHT REMITTANCE RRR 3542552639 | E37: 185202.57 | G37: =N(F37)-N(E37) -> -185202.57 | H37: =MONTH(B37) -> 1 | I37: WHT Remittance | J37: Operating | K37: Clear | L37: Matched | M37: CB-0034
A38: 34 | B38: 45680 | C38: FT250123403934 | D38: ONLINE GATEWAY SETTLEMENT BATCH 79677 | F38: 615346.61 | G38: =N(F38)-N(E38) -> 615346.61 | H38: =MONTH(B38) -> 1 | I38: Sales - Online Gateway Settlements | J38: Operating | K38: Clear | L38: Matched | M38: CB-0035 | N38: Net of gateway fees.
A39: 35 | B39: 45680 | C39: POS250123644785 | D39: POS PURCHASE - PETRO STATION 1670 IKEJA | E39: 255328.23 | G39: =N(F39)-N(E39) -> -255328.23 | H39: =MONTH(B39) -> 1 | I39: Fuel & Logistics | J39: Operating | K39: Clear | L39: Matched | M39: CB-0036 | N39: Could be generator diesel or vehicle fuel - same expense class, different cost centre.
A40: 36 | B40: 45681 | C40: FT250124165287 | D40: TRF FRM IBRAHIM K./PAYMENT | F40: 1558800 | G40: =N(F40)-N(E40) -> 1558800 | H40: =MONTH(B40) -> 1 | I40: Sales - Customer Transfers | J40: Operating | K40: Unclear | L40: Matched | M40: CB-0038 | N40: Individual sender, no invoice reference. Most likely a customer payment, but could be owner funding or a personal transfer. Confirm against sales invoices / customer list.
A41: 37 | B41: 45681 | C41: CHQ250124203381 | D41: CASH WITHDRAWAL - CHQ 004511 | E41: 413000 | G41: =N(F41)-N(E41) -> -413000 | H41: =MONTH(B41) -> 1 | I41: Petty Cash Withdrawals | J41: Operating | K41: Unclear | L41: Matched | M41: CB-0033 | N41: Cash cheque with no purpose stated. Treat as petty cash/float; support needed for what it was spent on (or it may be owner drawings).
...

Sheet Recon Exceptions
A1: RECONCILIATION EXCEPTIONS - items that differ between bank statement and cash book
A2: Effect = amount that must be added (+) or deducted (-) from the balance of the side shown, to reach the adjusted (true) cash balance.
A4: Ref | B4: Date | C4: Description | D4: Type | E4: Bank Amount | F4: Cash Book Amount | G4: Side to Adjust | H4: Effect on Adjusted Balance | I4: Bank S/N | J4: Cash Book Ref | K4: Explanation
A5: R-001 | B5: 45693 | C5: BROADBAND SUBSCRIPTION INV 82604 | D5: Timing difference (cleared in later month) | E5: 85000 | F5: 85000 | G5: None | H5: 0 | I5: 51 | J5: CB-0043 | K5: Booked 31-Jan but cleared by the bank 05-Feb: reconciling item at month end only.
A6: R-002 | B6: 45719 | C6: POWER DISCO PREPAID VEND MTR 4521830 | D6: Timing difference (cleared in later month) | E6: 211000 | F6: 211000 | G6: None | H6: 0 | I6: 93 | J6: CB-0083 | K6: Booked 28-Feb but cleared by the bank 03-Mar: reconciling item at month end only.
A7: R-003 | B7: 45721 | C7: BROADBAND SUBSCRIPTION INV 50891 | D7: Timing difference (cleared in later month) | E7: 85000 | F7: 85000 | G7: None | H7: 0 | I7: 95 | J7: CB-0084 | K7: Booked 28-Feb but cleared by the bank 05-Mar: reconciling item at month end only.
A8: R-004 | B8: 45735 | C8: NIP TRF FROM DELTA FRESH MART/INV 1087 | D8: Amount error in cash book | E8: 1245000 | F8: 1254000 | G8: Book | H8: -9000 | I8: 121 | J8: CB-0114 | K8: Cash book shows 1,254,000 (digits transposed).
A9: R-005 | B9: 45747 | C9: INTEREST ON CREDIT BALANCE | D9: Bank credit not in cash book | E9: 50923.89 | G9: Book | H9: 50923.89 | I9: 136 | J9: - | K9: Bank-credited interest - not yet recorded in the books.
A10: R-006 | B10: 45749 | C10: CHQ PAID 004517 - UNITY CHEMICALS LTD | D10: Timing difference (cleared in later month) | E10: 3427900 | F10: 3427900 | G10: None | H10: 0 | I10: 142 | J10: CB-0128 | K10: Booked 28-Mar but cleared by the bank 02-Apr: reconciling item at month end only.
A11: R-007 | B11: 45750 | C11: POWER DISCO PREPAID VEND MTR 4521656 | D11: Timing difference (cleared in later month) | E11: 310800 | F11: 310800 | G11: None | H11: 0 | I11: 146 | J11: CB-0129 | K11: Booked 31-Mar but cleared by the bank 03-Apr: reconciling item at month end only.
A12: R-008 | B12: 45779 | C12: NIP TRF FROM DELTA FRESH MART/INV 1168 | D12: Timing difference (cleared in later month) | E12: 3454200 | F12: 3454200 | G12: None | H12: 0 | I12: 189 | J12: CB-0171 | K12: Booked 30-Apr but cleared by the bank 02-May: reconciling item at month end only.
A13: R-009 | B13: 45810 | C13: CHQ PAID 004523 - UNITY CHEMICALS LTD | D13: Timing difference (cleared in later month) | E13: 2851100 | F13: 2851100 | G13: None | H13: 0 | I13: 234 | J13: CB-0211 | K13: Booked 29-May but cleared by the bank 02-Jun: reconciling item at month end only.
A14: R-010 | B14: 45811 | C14: NIP TRF TO ZENITH CRATES & PALLETS/INV 4494 | D14: Timing difference (cleared in later month) | E14: 950800 | F14: 950800 | G14: None | H14: 0 | I14: 236 | J14: CB-0212 | K14: Booked 29-May but cleared by the bank 03-Jun: reconciling item at month end only.
A15: R-011 | B15: 45838 | C15: INTEREST ON CREDIT BALANCE | D15: Bank credit not in cash book | E15: 37770.74 | G15: Book | H15: 37770.74 | I15: 278 | J15: - | K15: Bank-credited interest - not yet recorded in the books.
A16: R-012 | B16: 45852 | C16: NIP TRF TO PINNACLE PACKAGING LTD/INV 3309 | D16: Bank debit not in cash book | E16: 1850000 | G16: Book | H16: -1850000 | I16: 304 | J16: - | K16: Identical debit on same day - duplicate posted by bank, reversed on 15 Jul.
A17: R-013 | B17: 45853 | C17: REV/DUP DEBIT NIP 0712 PINNACLE PACKAGING | D17: Bank credit not in cash book | E17: 1850000 | G17: Book | H17: 1850000 | I17: 306 | J17: - | K17: Reversal of duplicate debit - nets to zero with the 12 Jul duplicate.
A18: R-014 | B18: 45873 | C18: NIP TRF FROM GREENFIELD STORES LTD/INV 1234 | D18: Timing difference (cleared in later month) | E18: 3188800 | F18: 3188800 | G18: None | H18: 0 | I18: 333 | J18: CB-0300 | K18: Booked 31-Jul but cleared by the bank 04-Aug: reconciling item at month end only.
A19: R-015 | B19: 45873 | C19: CHQ PAID 004529 - UNITY CHEMICALS LTD | D19: Timing difference (cleared in later month) | E19: 2687600 | F19: 2687600 | G19: None | H19: 0 | I19: 334 | J19: CB-0299 | K19: Booked 30-Jul but cleared by the bank 04-Aug: reconciling item at month end only.
A20: R-016 | B20: 45874 | C20: Payment - Unity Chemicals Inv 4630 (entered twice) | D20: Duplicate entry in cash book | E20: 1380000 | F20: 2760000 | G20: Book | H20: 1380000 | I20: - | J20: CB-0305 | K20: Same payment recorded twice in the cash book.
A21: R-017 | B21: 45891 | C21: RETURNED CHEQUE - UNPAID CHQ 007321 | D21: Bank debit not in cash book | E21: 2100000 | G21: Book | H21: -2100000 | I21: 372 | J21: - | K21: Dishonoured customer cheque - reinstate the debtor; not an expense.
A22: R-018 | B22: 45891 | C22: UNPAID CHEQUE COMMISSION INCL VAT | D22: Bank debit not in cash book | E22: 5375 | G22: Book | H22: -5375 | I22: 373 | J22: - | K22: On the bank statement but never entered in the cash book.
A23: R-019 | B23: 45930 | C23: INTEREST ON CREDIT BALANCE | D23: Bank credit not in cash book | E23: 44903.69 | G23: Book | H23: 44903.69 | I23: 423 | J23: - | K23: Bank-credited interest - not yet recorded in the books.
A24: R-020 | B24: 45932 | C24: CHQ PAID 004535 - ZENITH CRATES & PALLETS | D24: Timing difference (cleared in later month) | E24: 2484200 | F24: 2484200 | G24: None | H24: 0 | I24: 430 | J24: CB-0386 | K24: Booked 29-Sep but cleared by the bank 02-Oct: reconciling item at month end only.
A25: R-021 | B25: 45938 | C25: NIP TRF TO KEMI PLASTICS LTD/INV 4702 | D25: Amount error in cash book | E25: 2716500 | F25: 2761500 | G25: Book | H25: 45000 | I25: 439 | J25: CB-0396 | K25: Cash book shows 2,761,500 (digits transposed).
A26: R-022 | B26: 45940 | C26: DIRECT DEBIT - LOAN REPAYMENT TL/2025/0310 INSTL 7 | D26: Bank debit not in cash book | E26: 1057421.9 | G26: Book | H26: -1057421.9 | I26: 444 | J26: - | K26: Single debit combines principal and interest - split using Loan Schedule sheet.
A27: R-023 | B27: 45961 | C27: ACCOUNT MAINTENANCE FEE OCT 2025 | D27: Bank debit not in cash book | E27: 4500 | G27: Book | H27: -4500 | I27: 475 | J27: - | K27: Not yet recorded in the cash book.
A28: R-024 | B28: 45961 | C28: SMS ALERT CHARGES | D28: Bank debit not in cash book | E28: 4393.63 | G28: Book | H28: -4393.63 | I28: 476 | J28: - | K28: Not yet recorded in the cash book.
A29: R-025 | B29: 45961 | C29: NIP TRANSFER FEES (10 TXNS) | D29: Bank debit not in cash book | E29: 500 | G29: Book | H29: -500 | I29: 477 | J29: - | K29: Not yet recorded in the cash book.
A30: R-026 | B30: 45961 | C30: VAT ON BANK CHARGES 7.5% | D30: Bank debit not in cash book | E30: 704.52 | G30: Book | H30: -704.52 | I30: 478 | J30: - | K30: Not yet recorded in the cash book.
A31: R-027 | B31: 45961 | C31: STAMP DUTY ON 17 ELECTRONIC RECEIPTS | D31: Bank debit not in cash book | E31: 850 | G31: Book | H31: -850 | I31: 479 | J31: - | K31: Not yet recorded in the cash book.
A32: R-028 | B32: 45964 | C32: POS PURCHASE - PETRO STATION 1719 IKEJA | D32: Timing difference (cleared in later month) | E32: 153012.19 | F32: 153012.19 | G32: None | H32: 0 | I32: 482 | J32: CB-0432 | K32: Booked 30-Oct but cleared by the bank 03-Nov: reconciling item at month end only.
A33: R-029 | B33: 45966 | C33: COMMISSION ON FX / SWIFT CHARGES | D33: Bank debit not in cash book | E33: 46200 | G33: Book | H33: -46200 | I33: 488 | J33: - | K33: On the bank statement but never entered in the cash book.
A34: R-030 | B34: 45966 | C34: NIP TRF TO BRIGHTPRINT MEDIA/FLYERS 118 | D34: Timing difference (cleared in later month) | E34: 276952.5 | F34: 276952.5 | G34: None | H34: 0 | I34: 486 | J34: CB-0433 | K34: Booked 31-Oct but cleared by the bank 05-Nov: reconciling item at month end only.
A35: R-031 | B35: 45971 | C35: DIRECT DEBIT - LOAN REPAYMENT TL/2025/0310 INSTL 8 | D35: Bank debit not in cash book | E35: 1057421.9 | G35: Book | H35: -1057421.9 | I35: 498 | J35: - | K35: Single debit combines principal and interest - split using Loan Schedule sheet.
A36: R-032 | B36: 45989 | C36: ACCOUNT MAINTENANCE FEE NOV 2025 | D36: Bank debit not in cash book | E36: 4500 | G36: Book | H36: -4500 | I36: 521 | J36: - | K36: Not yet recorded in the cash book.
A37: R-033 | B37: 45989 | C37: SMS ALERT CHARGES | D37: Bank debit not in cash book | E37: 4590.35 | G37: Book | H37: -4590.35 | I37: 522 | J37: - | K37: Not yet recorded in the cash book.
A38: R-034 | B38: 45989 | C38: NIP TRANSFER FEES (6 TXNS) | D38: Bank debit not in cash book | E38: 300 | G38: Book | H38: -300 | I38: 523 | J38: - | K38: Not yet recorded in the cash book.
A39: R-035 | B39: 45989 | C39: VAT ON BANK CHARGES 7.5% | D39: Bank debit not in cash book | E39: 704.28 | G39: Book | H39: -704.28 | I39: 524 | J39: - | K39: Not yet recorded in the cash book.
A40: R-036 | B40: 45989 | C40: STAMP DUTY ON 15 ELECTRONIC RECEIPTS | D40: Bank debit not in cash book | E40: 750 | G40: Book | H40: -750 | I40: 525 | J40: - | K40: Not yet recorded in the cash book.
A41: R-037 | B41: 46001 | C41: DIRECT DEBIT - LOAN REPAYMENT TL/2025/0310 INSTL 9 | D41: Bank debit not in cash book | E41: 1057421.9 | G41: Book | H41: -1057421.9 | I41: 540 | J41: - | K41: Single debit combines principal and interest - split using Loan Schedule sheet.
...

Sheet Bank Rec
A1: BANK RECONCILIATION STATEMENT AS AT 31 DECEMBER 2025
A2: Lagosmart Distribution Ltd (fictional) | All amounts in NGN. Items pulled from the Recon Exceptions sheet by type.
A4: A. BANK SIDE
A5: Balance per bank statement at 31 Dec 2025 | C5: ='Bank Statement'!H581 -> 1.1181209e+08
A6: Add: Deposits in transit | C6: =SUMIFS('Recon Exceptions'!$H$5:$H$54,'Recon Exceptions'!$D$5:$D$54,"Deposit in transit") -> 6200000
A7: Less: Outstanding (unpresented) cheques | C7: =SUMIFS('Recon Exceptions'!$H$5:$H$54,'Recon Exceptions'!$D$5:$D$54,"Outstanding cheque") -> -4705000
A8: Adjusted bank balance | C8: =SUM(C5:C7) -> 1.1330709e+08
A10: B. CASH BOOK SIDE
A11: Balance per cash book at 31 Dec 2025 | C11: ='Cash Book'!F523 -> 1.1707301e+08
A12: Add: Bank credits not yet in cash book (interest, reversals) | C12: =SUMIFS('Recon Exceptions'!$H$5:$H$54,'Recon Exceptions'!$D$5:$D$54,"Bank credit not in cash book") -> 2024205.6
A13: Less: Bank debits not yet in cash book (charges, loan repayments, dishonoured cheque, bank duplicate) | C13: =SUMIFS('Recon Exceptions'!$H$5:$H$54,'Recon Exceptions'!$D$5:$D$54,"Bank debit not in cash book") -> -7206126.1
A14: Correct: Amount errors in cash book (net) | C14: =SUMIFS('Recon Exceptions'!$H$5:$H$54,'Recon Exceptions'!$D$5:$D$54,"Amount error in cash book") -> 36000
A15: Add back: Duplicate payment entry in cash book | C15: =SUMIFS('Recon Exceptions'!$H$5:$H$54,'Recon Exceptions'!$D$5:$D$54,"Duplicate entry in cash book") -> 1380000
A16: Adjusted cash book balance | C16: =SUM(C11:C15) -> 1.1330709e+08
A18: DIFFERENCE (must be zero) | C18: =ROUND(C8-C16,2) -> 0
A20: Note: timing differences that cleared in a later month have no effect at 31 Dec and are therefore excluded here.
A21: Journals needed in the books = Section B items (rows 12-15). Rows 6-7 need no journal.

Sheet Loan Schedule
A1: TERM LOAN AMORTISATION SCHEDULE - TL/2025/0310
A3: Loan principal (NGN) | C3: 20000000 | E3: Blue = input. Rate assumption: 24% p.a. on reducing balance, interest = opening balance x rate / 12.
A4: Annual interest rate | C4: 0.24
A5: Term (months) | C5: 24
A6: Drawdown date | C6: 45726
A7: First instalment date | C7: 45757
A8: Monthly instalment (NGN) | C8: =ROUND(-PMT(C4/12,C5,C3),2) -> 1057421.9
A10: No. | B10: Due Date | C10: Year | D10: Month | E10: Opening Balance | F10: Instalment | G10: Interest | H10: Principal | I10: Closing Balance
A11: 1 | B11: =EDATE($C$7,A11-1) -> 45757 | C11: =YEAR(B11) -> 2025 | D11: =MONTH(B11) -> 4 | E11: =$C$3 -> 20000000 | F11: =$C$8 -> 1057421.9 | G11: =ROUND(E11*$C$4/12,2) -> 400000 | H11: =F11-G11 -> 657421.95 | I11: =E11-H11 -> 19342578
A12: 2 | B12: =EDATE($C$7,A12-1) -> 45787 | C12: =YEAR(B12) -> 2025 | D12: =MONTH(B12) -> 5 | E12: =I11 -> 19342578 | F12: =$C$8 -> 1057421.9 | G12: =ROUND(E12*$C$4/12,2) -> 386851.56 | H12: =F12-G12 -> 670570.39 | I12: =E12-H12 -> 18672008
A13: 3 | B13: =EDATE($C$7,A13-1) -> 45818 | C13: =YEAR(B13) -> 2025 | D13: =MONTH(B13) -> 6 | E13: =I12 -> 18672008 | F13: =$C$8 -> 1057421.9 | G13: =ROUND(E13*$C$4/12,2) -> 373440.15 | H13: =F13-G13 -> 683981.8 | I13: =E13-H13 -> 17988026
A14: 4 | B14: =EDATE($C$7,A14-1) -> 45848 | C14: =YEAR(B14) -> 2025 | D14: =MONTH(B14) -> 7 | E14: =I13 -> 17988026 | F14: =$C$8 -> 1057421.9 | G14: =ROUND(E14*$C$4/12,2) -> 359760.52 | H14: =F14-G14 -> 697661.43 | I14: =E14-H14 -> 17290364
A15: 5 | B15: =EDATE($C$7,A15-1) -> 45879 | C15: =YEAR(B15) -> 2025 | D15: =MONTH(B15) -> 8 | E15: =I14 -> 17290364 | F15: =$C$8 -> 1057421.9 | G15: =ROUND(E15*$C$4/12,2) -> 345807.29 | H15: =F15-G15 -> 711614.66 | I15: =E15-H15 -> 16578750
A16: 6 | B16: =EDATE($C$7,A16-1) -> 45910 | C16: =YEAR(B16) -> 2025 | D16: =MONTH(B16) -> 9 | E16: =I15 -> 16578750 | F16: =$C$8 -> 1057421.9 | G16: =ROUND(E16*$C$4/12,2) -> 331575 | H16: =F16-G16 -> 725846.95 | I16: =E16-H16 -> 15852903
A17: 7 | B17: =EDATE($C$7,A17-1) -> 45940 | C17: =YEAR(B17) -> 2025 | D17: =MONTH(B17) -> 10 | E17: =I16 -> 15852903 | F17: =$C$8 -> 1057421.9 | G17: =ROUND(E17*$C$4/12,2) -> 317058.06 | H17: =F17-G17 -> 740363.89 | I17: =E17-H17 -> 15112539
A18: 8 | B18: =EDATE($C$7,A18-1) -> 45971 | C18: =YEAR(B18) -> 2025 | D18: =MONTH(B18) -> 11 | E18: =I17 -> 15112539 | F18: =$C$8 -> 1057421.9 | G18: =ROUND(E18*$C$4/12,2) -> 302250.78 | H18: =F18-G18 -> 755171.17 | I18: =E18-H18 -> 14357368
A19: 9 | B19: =EDATE($C$7,A19-1) -> 46001 | C19: =YEAR(B19) -> 2025 | D19: =MONTH(B19) -> 12 | E19: =I18 -> 14357368 | F19: =$C$8 -> 1057421.9 | G19: =ROUND(E19*$C$4/12,2) -> 287147.36 | H19: =F19-G19 -> 770274.59 | I19: =E19-H19 -> 13587093
A20: 10 | B20: =EDATE($C$7,A20-1) -> 46032 | C20: =YEAR(B20) -> 2026 | D20: =MONTH(B20) -> 1 | E20: =I19 -> 13587093 | F20: =$C$8 -> 1057421.9 | G20: =ROUND(E20*$C$4/12,2) -> 271741.86 | H20: =F20-G20 -> 785680.09 | I20: =E20-H20 -> 12801413
A21: 11 | B21: =EDATE($C$7,A21-1) -> 46063 | C21: =YEAR(B21) -> 2026 | D21: =MONTH(B21) -> 2 | E21: =I20 -> 12801413 | F21: =$C$8 -> 1057421.9 | G21: =ROUND(E21*$C$4/12,2) -> 256028.26 | H21: =F21-G21 -> 801393.69 | I21: =E21-H21 -> 12000019
A22: 12 | B22: =EDATE($C$7,A22-1) -> 46091 | C22: =YEAR(B22) -> 2026 | D22: =MONTH(B22) -> 3 | E22: =I21 -> 12000019 | F22: =$C$8 -> 1057421.9 | G22: =ROUND(E22*$C$4/12,2) -> 240000.39 | H22: =F22-G22 -> 817421.56 | I22: =E22-H22 -> 11182598
A23: 13 | B23: =EDATE($C$7,A23-1) -> 46122 | C23: =YEAR(B23) -> 2026 | D23: =MONTH(B23) -> 4 | E23: =I22 -> 11182598 | F23: =$C$8 -> 1057421.9 | G23: =ROUND(E23*$C$4/12,2) -> 223651.96 | H23: =F23-G23 -> 833769.99 | I23: =E23-H23 -> 10348828
... A33: 23 | B33: =EDATE($C$7,A33-1) -> 46428 | C33: =YEAR(B33) -> 2027 | D33: =MONTH(B33) -> 2 | E33: =I32 -> 2053049.1 | F33: =$C$8 -> 1057421.9 | G33: =ROUND(E33*$C$4/12,2) -> 41060.98 | H33: =F33-G33 -> 1016361 | I33: =E33-H33 -> 1036688.1
A34: 24 | B34: =EDATE($C$7,A34-1) -> 46456 | C34: =YEAR(B34) -> 2027 | D34: =MONTH(B34) -> 3 | E34: =I33 -> 1036688.1 | F34: =E34+G34 -> 1057421.8 | G34: =ROUND(E34*$C$4/12,2) -> 20733.76 | H34: =F34-G34 -> 1036688.1 | I34: =E34-H34 -> 0
A36: Summary for the financial statements
A37: 2025 instalments paid (cash) | C37: =SUMIFS(F11:F34,C11:C34,2025) -> 9516797.6
A38: 2025 interest expense (paid) | C38: =SUMIFS(G11:G34,C11:C34,2025) -> 3103890.7
A39: 2025 principal repaid | C39: =SUMIFS(H11:H34,C11:C34,2025) -> 6412906.8
A40: Loan balance at 31 Dec 2025 | C40: =INDEX(I11:I34,MATCH(DATE(2025,12,10),B11:B34,0)) -> 13587093
A41: of which: current portion (principal due in 2026) | C41: =SUMIFS(H11:H34,C11:C34,2026) -> 10537612
A42: of which: non-current portion | C42: =C40-C41 -> 3049481.4
A43: Interest accrued 10 Dec - 31 Dec 2025 (21 days approx., accrual) | C43: =ROUND(C40*C4/12*21/31,2) -> 184083.2

Sheet Monthly Summary
A1: MONTHLY CASH SUMMARY BY CATEGORY - 2025 (receipts positive, payments negative)
A2: Built with SUMIFS on the Answer Key sheet. Replace the Answer Key categories with your classifier output to compare.
B4: Month no. | C4: 1 | D4: 2 | E4: 3 | F4: 4 | G4: 5 | H4: 6 | I4: 7 | J4: 8 | K4: 9 | L4: 10 | M4: 11 | N4: 12
A5: Category | B5: FS Class | C5: Jan-25 | D5: Feb-25 | E5: Mar-25 | F5: Apr-25 | G5: May-25 | H5: Jun-25 | I5: Jul-25 | J5: Aug-25 | K5: Sep-25 | L5: Oct-25 | M5: Nov-25 | N5: Dec-25 | O5: Total
A6: Sales - Customer Transfers | B6: Operating | C6: =SUMIFS('Answer Key'!$G$5:$G$577,'Answer Key'!$I$5:$I$577,$A6,'Answer Key'!$H$5:$H$577,C$4) -> 18875900 | D6: =SUMIFS('Answer Key'!$G$5:$G$577,'Answer Key'!$I$5:$I$577,$A6,'Answer Key'!$H$5:$H$577,D$4) -> 25996500 | E6: =SUMIFS('Answer Key'!$G$5:$G$577,'Answer Key'!$I$5:$I$577,$A6,'Answer Key'!$H$5:$H$577,E$4) -> 16819700 | F6: =SUMIFS('Answer Key'!$G$5:$G$577,'Answer Key'!$I$5:$I$577,$A6,'Answer Key'!$H$5:$H$577,F$4) -> 17115500 | G6: =SUMIFS('Answer Key'!$G$5:$G$577,'Answer Key'!$I$5:$I$577,$A6,'Answer Key'!$H$5:$H$577,G$4) -> 22872800 | H6: =SUMIFS('Answer Key'!$G$5:$G$577,'Answer Key'!$I$5:$I$577,$A6,'Answer Key'!$H$5:$H$577,H$4) -> 18537300 | I6: =SUMIFS('Answer Key'!$G$5:$G$577,'Answer Key'!$I$5:$I$577,$A6,'Answer Key'!$H$5:$H$577,I$4) -> 26808600 | J6: =SUMIFS('Answer Key'!$G$5:$G$577,'Answer Key'!$I$5:$I$577,$A6,'Answer Key'!$H$5:$H$577,J$4) -> 25182000 | ... N6: =SUMIFS('Answer Key'!$G$5:$G$577,'Answer Key'!$I$5:$I$577,$A6,'Answer Key'!$H$5:$H$577,N$4) -> 31294800 | O6: =SUM(C6:N6) -> 280774500
A7: Sales - POS Settlements | B7: Operating | C7: =SUMIFS('Answer Key'!$G$5:$G$577,'Answer Key'!$I$5:$I$577,$A7,'Answer Key'!$H$5:$H$577,C$4) -> 5374492.1 | D7: =SUMIFS('Answer Key'!$G$5:$G$577,'Answer Key'!$I$5:$I$577,$A7,'Answer Key'!$H$5:$H$577,D$4) -> 5477192.8 | E7: =SUMIFS('Answer Key'!$G$5:$G$577,'Answer Key'!$I$5:$I$577,$A7,'Answer Key'!$H$5:$H$577,E$4) -> 6448886.2 | F7: =SUMIFS('Answer Key'!$G$5:$G$577,'Answer Key'!$I$5:$I$577,$A7,'Answer Key'!$H$5:$H$577,F$4) -> 5431331.5 | G7: =SUMIFS('Answer Key'!$G$5:$G$577,'Answer Key'!$I$5:$I$577,$A7,'Answer Key'!$H$5:$H$577,G$4) -> 5108676.7 | H7: =SUMIFS('Answer Key'!$G$5:$G$577,'Answer Key'!$I$5:$I$577,$A7,'Answer Key'!$H$5:$H$577,H$4) -> 4764409.4 | I7: =SUMIFS('Answer Key'!$G$5:$G$577,'Answer Key'!$I$5:$I$577,$A7,'Answer Key'!$H$5:$H$577,I$4) -> 4588456.8 | J7: =SUMIFS('Answer Key'!$G$5:$G$577,'Answer Key'!$I$5:$I$577,$A7,'Answer Key'!$H$5:$H$577,J$4) -> 5948416.8 | ... N7: =SUMIFS('Answer Key'!$G$5:$G$577,'Answer Key'!$I$5:$I$577,$A7,'Answer Key'!$H$5:$H$577,N$4) -> 7171435.4 | O7: =SUM(C7:N7) -> 70098625
A8: Sales - Online Gateway Settlements | B8: Operating | C8: =SUMIFS('Answer Key'!$G$5:$G$577,'Answer Key'!$I$5:$I$577,$A8,'Answer Key'!$H$5:$H$577,C$4) -> 1395882.9 | D8: =SUMIFS('Answer Key'!$G$5:$G$577,'Answer Key'!$I$5:$I$577,$A8,'Answer Key'!$H$5:$H$577,D$4) -> 1411032.8 | E8: =SUMIFS('Answer Key'!$G$5:$G$577,'Answer Key'!$I$5:$I$577,$A8,'Answer Key'!$H$5:$H$577,E$4) -> 1456829.6 | F8: =SUMIFS('Answer Key'!$G$5:$G$577,'Answer Key'!$I$5:$I$577,$A8,'Answer Key'!$H$5:$H$577,F$4) -> 1634876.2 | G8: =SUMIFS('Answer Key'!$G$5:$G$577,'Answer Key'!$I$5:$I$577,$A8,'Answer Key'!$H$5:$H$577,G$4) -> 1402872.9 | H8: =SUMIFS('Answer Key'!$G$5:$G$577,'Answer Key'!$I$5:$I$577,$A8,'Answer Key'!$H$5:$H$577,H$4) -> 1274046.9 | I8: =SUMIFS('Answer Key'!$G$5:$G$577,'Answer Key'!$I$5:$I$577,$A8,'Answer Key'!$H$5:$H$577,I$4) -> 881111.61 | J8: =SUMIFS('Answer Key'!$G$5:$G$577,'Answer Key'!$I$5:$I$577,$A8,'Answer Key'!$H$5:$H$577,J$4) -> 1515401.4 | ... N8: =SUMIFS('Answer Key'!$G$5:$G$577,'Answer Key'!$I$5:$I$577,$A8,'Answer Key'!$H$5:$H$577,N$4) -> 2772014.2 | O8: =SUM(C8:N8) -> 18525702
A9: Sales - Cash Deposits | B9: Operating | C9: =SUMIFS('Answer Key'!$G$5:$G$577,'Answer Key'!$I$5:$I$577,$A9,'Answer Key'!$H$5:$H$577,C$4) -> 2494622.4 | D9: =SUMIFS('Answer Key'!$G$5:$G$577,'Answer Key'!$I$5:$I$577,$A9,'Answer Key'!$H$5:$H$577,D$4) -> 3277878.9 | E9: =SUMIFS('Answer Key'!$G$5:$G$577,'Answer Key'!$I$5:$I$577,$A9,'Answer Key'!$H$5:$H$577,E$4) -> 3337495.2 | F9: =SUMIFS('Answer Key'!$G$5:$G$577,'Answer Key'!$I$5:$I$577,$A9,'Answer Key'!$H$5:$H$577,F$4) -> 2514041 | G9: =SUMIFS('Answer Key'!$G$5:$G$577,'Answer Key'!$I$5:$I$577,$A9,'Answer Key'!$H$5:$H$577,G$4) -> 2165363.2 | H9: =SUMIFS('Answer Key'!$G$5:$G$577,'Answer Key'!$I$5:$I$577,$A9,'Answer Key'!$H$5:$H$577,H$4) -> 2700062.9 | I9: =SUMIFS('Answer Key'!$G$5:$G$577,'Answer Key'!$I$5:$I$577,$A9,'Answer Key'!$H$5:$H$577,I$4) -> 2879621.6 | J9: =SUMIFS('Answer Key'!$G$5:$G$577,'Answer Key'!$I$5:$I$577,$A9,'Answer Key'!$H$5:$H$577,J$4) -> 2815386.1 | ... N9: =SUMIFS('Answer Key'!$G$5:$G$577,'Answer Key'!$I$5:$I$577,$A9,'Answer Key'!$H$5:$H$577,N$4) -> 3729256 | O9: =SUM(C9:N9) -> 35048165
A10: Sales - Cheque Deposits | B10: Operating | C10: =SUMIFS('Answer Key'!$G$5:$G$577,'Answer Key'!$I$5:$I$577,$A10,'Answer Key'!$H$5:$H$577,C$4) -> 0 | D10: =SUMIFS('Answer Key'!$G$5:$G$577,'Answer Key'!$I$5:$I$577,$A10,'Answer Key'!$H$5:$H$577,D$4) -> 0 | E10: =SUMIFS('Answer Key'!$G$5:$G$577,'Answer Key'!$I$5:$I$577,$A10,'Answer Key'!$H$5:$H$577,E$4) -> 0 | F10: =SUMIFS('Answer Key'!$G$5:$G$577,'Answer Key'!$I$5:$I$577,$A10,'Answer Key'!$H$5:$H$577,F$4) -> 0 | G10: =SUMIFS('Answer Key'!$G$5:$G$577,'Answer Key'!$I$5:$I$577,$A10,'Answer Key'!$H$5:$H$577,G$4) -> 0 | H10: =SUMIFS('Answer Key'!$G$5:$G$577,'Answer Key'!$I$5:$I$577,$A10,'Answer Key'!$H$5:$H$577,H$4) -> 0 | I10: =SUMIFS('Answer Key'!$G$5:$G$577,'Answer Key'!$I$5:$I$577,$A10,'Answer Key'!$H$5:$H$577,I$4) -> 0 | J10: =SUMIFS('Answer Key'!$G$5:$G$577,'Answer Key'!$I$5:$I$577,$A10,'Answer Key'!$H$5:$H$577,J$4) -> 2100000 | ... N10: =SUMIFS('Answer Key'!$G$5:$G$577,'Answer Key'!$I$5:$I$577,$A10,'Answer Key'!$H$5:$H$577,N$4) -> 0 | O10: =SUM(C10:N10) -> 2100000
A11: Supplier Refund / Credit Note | B11: Operating | C11: =SUMIFS('Answer Key'!$G$5:$G$577,'Answer Key'!$I$5:$I$577,$A11,'Answer Key'!$H$5:$H$577,C$4) -> 0 | D11: =SUMIFS('Answer Key'!$G$5:$G$577,'Answer Key'!$I$5:$I$577,$A11,'Answer Key'!$H$5:$H$577,D$4) -> 0 | E11: =SUMIFS('Answer Key'!$G$5:$G$577,'Answer Key'!$I$5:$I$577,$A11,'Answer Key'!$H$5:$H$577,E$4) -> 0 | F11: =SUMIFS('Answer Key'!$G$5:$G$577,'Answer Key'!$I$5:$I$577,$A11,'Answer Key'!$H$5:$H$577,F$4) -> 0 | G11: =SUMIFS('Answer Key'!$G$5:$G$577,'Answer Key'!$I$5:$I$577,$A11,'Answer Key'!$H$5:$H$577,G$4) -> 320000 | H11: =SUMIFS('Answer Key'!$G$5:$G$577,'Answer Key'!$I$5:$I$577,$A11,'Answer Key'!$H$5:$H$577,H$4) -> 0 | I11: =SUMIFS('Answer Key'!$G$5:$G$577,'Answer Key'!$I$5:$I$577,$A11,'Answer Key'!$H$5:$H$577,I$4) -> 0 | J11: =SUMIFS('Answer Key'!$G$5:$G$577,'Answer Key'!$I$5:$I$577,$A11,'Answer Key'!$H$5:$H$577,J$4) -> 0 | ... N11: =SUMIFS('Answer Key'!$G$5:$G$577,'Answer Key'!$I$5:$I$577,$A11,'Answer Key'!$H$5:$H$577,N$4) -> 0 | O11: =SUM(C11:N11) -> 320000
A12: Interest Income | B12: Operating | C12: =SUMIFS('Answer Key'!$G$5:$G$577,'Answer Key'!$I$5:$I$577,$A12,'Answer Key'!$H$5:$H$577,C$4) -> 0 | D12: =SUMIFS('Answer Key'!$G$5:$G$577,'Answer Key'!$I$5:$I$577,$A12,'Answer Key'!$H$5:$H$577,D$4) -> 0 | E12: =SUMIFS('Answer Key'!$G$5:$G$577,'Answer Key'!$I$5:$I$577,$A12,'Answer Key'!$H$5:$H$577,E$4) -> 50923.89 | F12: =SUMIFS('Answer Key'!$G$5:$G$577,'Answer Key'!$I$5:$I$577,$A12,'Answer Key'!$H$5:$H$577,F$4) -> 0 | G12: =SUMIFS('Answer Key'!$G$5:$G$577,'Answer Key'!$I$5:$I$577,$A12,'Answer Key'!$H$5:$H$577,G$4) -> 0 | H12: =SUMIFS('Answer Key'!$G$5:$G$577,'Answer Key'!$I$5:$I$577,$A12,'Answer Key'!$H$5:$H$577,H$4) -> 37770.74 | I12: =SUMIFS('Answer Key'!$G$5:$G$577,'Answer Key'!$I$5:$I$577,$A12,'Answer Key'!$H$5:$H$577,I$4) -> 0 | J12: =SUMIFS('Answer Key'!$G$5:$G$577,'Answer Key'!$I$5:$I$577,$A12,'Answer Key'!$H$5:$H$577,J$4) -> 0 | ... N12: =SUMIFS('Answer Key'!$G$5:$G$577,'Answer Key'!$I$5:$I$577,$A12,'Answer Key'!$H$5:$H$577,N$4) -> 40607.24 | O12: =SUM(C12:N12) -> 174205.56
A13: Returned Cheque (Dishonoured) | B13: Operating | C13: =SUMIFS('Answer Key'!$G$5:$G$577,'Answer Key'!$I$5:$I$577,$A13,'Answer Key'!$H$5:$H$577,C$4) -> 0 | D13: =SUMIFS('Answer Key'!$G$5:$G$577,'Answer Key'!$I$5:$I$577,$A13,'Answer Key'!$H$5:$H$577,D$4) -> 0 | E13: =SUMIFS('Answer Key'!$G$5:$G$577,'Answer Key'!$I$5:$I$577,$A13,'Answer Key'!$H$5:$H$577,E$4) -> 0 | F13: =SUMIFS('Answer Key'!$G$5:$G$577,'Answer Key'!$I$5:$I$577,$A13,'Answer Key'!$H$5:$H$577,F$4) -> 0 | G13: =SUMIFS('Answer Key'!$G$5:$G$577,'Answer Key'!$I$5:$I$577,$A13,'Answer Key'!$H$5:$H$577,G$4) -> 0 | H13: =SUMIFS('Answer Key'!$G$5:$G$577,'Answer Key'!$I$5:$I$577,$A13,'Answer Key'!$H$5:$H$577,H$4) -> 0 | I13: =SUMIFS('Answer Key'!$G$5:$G$577,'Answer Key'!$I$5:$I$577,$A13,'Answer Key'!$H$5:$H$577,I$4) -> 0 | J13: =SUMIFS('Answer Key'!$G$5:$G$577,'Answer Key'!$I$5:$I$577,$A13,'Answer Key'!$H$5:$H$577,J$4) -> -2100000 | ... N13: =SUMIFS('Answer Key'!$G$5:$G$577,'Answer Key'!$I$5:$I$577,$A13,'Answer Key'!$H$5:$H$577,N$4) -> 0 | O13: =SUM(C13:N13) -> -2100000
A14: Inventory / Supplier Payments | B14: Operating | C14: =SUMIFS('Answer Key'!$G$5:$G$577,'Answer Key'!$I$5:$I$577,$A14,'Answer Key'!$H$5:$H$577,C$4) -> -10367600 | D14: =SUMIFS('Answer Key'!$G$5:$G$577,'Answer Key'!$I$5:$I$577,$A14,'Answer Key'!$H$5:$H$577,D$4) -> -5945700 | E14: =SUMIFS('Answer Key'!$G$5:$G$577,'Answer Key'!$I$5:$I$577,$A14,'Answer Key'!$H$5:$H$577,E$4) -> -4737300 | F14: =SUMIFS('Answer Key'!$G$5:$G$577,'Answer Key'!$I$5:$I$577,$A14,'Answer Key'!$H$5:$H$577,F$4) -> -15913300 | G14: =SUMIFS('Answer Key'!$G$5:$G$577,'Answer Key'!$I$5:$I$577,$A14,'Answer Key'!$H$5:$H$577,G$4) -> -9956500 | H14: =SUMIFS('Answer Key'!$G$5:$G$577,'Answer Key'!$I$5:$I$577,$A14,'Answer Key'!$H$5:$H$577,H$4) -> -13118500 | I14: =SUMIFS('Answer Key'!$G$5:$G$577,'Answer Key'!$I$5:$I$577,$A14,'Answer Key'!$H$5:$H$577,I$4) -> -9964800 | J14: =SUMIFS('Answer Key'!$G$5:$G$577,'Answer Key'!$I$5:$I$577,$A14,'Answer Key'!$H$5:$H$577,J$4) -> -17110300 | ... N14: =SUMIFS('Answer Key'!$G$5:$G$577,'Answer Key'!$I$5:$I$577,$A14,'Answer Key'!$H$5:$H$577,N$4) -> -11858300 | O14: =SUM(C14:N14) -> -132181400
A15: Import Purchases (FX) | B15: Operating | C15: =SUMIFS('Answer Key'!$G$5:$G$577,'Answer Key'!$I$5:$I$577,$A15,'Answer Key'!$H$5:$H$577,C$4) -> 0 | D15: =SUMIFS('Answer Key'!$G$5:$G$577,'Answer Key'!$I$5:$I$577,$A15,'Answer Key'!$H$5:$H$577,D$4) -> 0 | E15: =SUMIFS('Answer Key'!$G$5:$G$577,'Answer Key'!$I$5:$I$577,$A15,'Answer Key'!$H$5:$H$577,E$4) -> 0 | F15: =SUMIFS('Answer Key'!$G$5:$G$577,'Answer Key'!$I$5:$I$577,$A15,'Answer Key'!$H$5:$H$577,F$4) -> 0 | G15: =SUMIFS('Answer Key'!$G$5:$G$577,'Answer Key'!$I$5:$I$577,$A15,'Answer Key'!$H$5:$H$577,G$4) -> 0 | H15: =SUMIFS('Answer Key'!$G$5:$G$577,'Answer Key'!$I$5:$I$577,$A15,'Answer Key'!$H$5:$H$577,H$4) -> 0 | I15: =SUMIFS('Answer Key'!$G$5:$G$577,'Answer Key'!$I$5:$I$577,$A15,'Answer Key'!$H$5:$H$577,I$4) -> 0 | J15: =SUMIFS('Answer Key'!$G$5:$G$577,'Answer Key'!$I$5:$I$577,$A15,'Answer Key'!$H$5:$H$577,J$4) -> 0 | ... N15: =SUMIFS('Answer Key'!$G$5:$G$577,'Answer Key'!$I$5:$I$577,$A15,'Answer Key'!$H$5:$H$577,N$4) -> 0 | O15: =SUM(C15:N15) -> -9240000
A16: Salaries & Wages | B16: Operating | C16: =SUMIFS('Answer Key'!$G$5:$G$577,'Answer Key'!$I$5:$I$577,$A16,'Answer Key'!$H$5:$H$577,C$4) -> -3781200 | D16: =SUMIFS('Answer Key'!$G$5:$G$577,'Answer Key'!$I$5:$I$577,$A16,'Answer Key'!$H$5:$H$577,D$4) -> -3781200 | E16: =SUMIFS('Answer Key'!$G$5:$G$577,'Answer Key'!$I$5:$I$577,$A16,'Answer Key'!$H$5:$H$577,E$4) -> -3781200 | F16: =SUMIFS('Answer Key'!$G$5:$G$577,'Answer Key'!$I$5:$I$577,$A16,'Answer Key'!$H$5:$H$577,F$4) -> -3781200 | G16: =SUMIFS('Answer Key'!$G$5:$G$577,'Answer Key'!$I$5:$I$577,$A16,'Answer Key'!$H$5:$H$577,G$4) -> -3781200 | H16: =SUMIFS('Answer Key'!$G$5:$G$577,'Answer Key'!$I$5:$I$577,$A16,'Answer Key'!$H$5:$H$577,H$4) -> -3781200 | I16: =SUMIFS('Answer Key'!$G$5:$G$577,'Answer Key'!$I$5:$I$577,$A16,'Answer Key'!$H$5:$H$577,I$4) -> -4085300 | J16: =SUMIFS('Answer Key'!$G$5:$G$577,'Answer Key'!$I$5:$I$577,$A16,'Answer Key'!$H$5:$H$577,J$4) -> -4085300 | ... N16: =SUMIFS('Answer Key'!$G$5:$G$577,'Answer Key'!$I$5:$I$577,$A16,'Answer Key'!$H$5:$H$577,N$4) -> -7762100 | O16: =SUM(C16:N16) -> -50875800
A17: PAYE Remittance | B17: Operating | C17: =SUMIFS('Answer Key'!$G$5:$G$577,'Answer Key'!$I$5:$I$577,$A17,'Answer Key'!$H$5:$H$577,C$4) -> -450800 | D17: =SUMIFS('Answer Key'!$G$5:$G$577,'Answer Key'!$I$5:$I$577,$A17,'Answer Key'!$H$5:$H$577,D$4) -> -450800 | E17: =SUMIFS('Answer Key'!$G$5:$G$577,'Answer Key'!$I$5:$I$577,$A17,'Answer Key'!$H$5:$H$577,E$4) -> -450800 | F17: =SUMIFS('Answer Key'!$G$5:$G$577,'Answer Key'!$I$5:$I$577,$A17,'Answer Key'!$H$5:$H$577,F$4) -> -450800 | G17: =SUMIFS('Answer Key'!$G$5:$G$577,'Answer Key'!$I$5:$I$577,$A17,'Answer Key'!$H$5:$H$577,G$4) -> -450800 | H17: =SUMIFS('Answer Key'!$G$5:$G$577,'Answer Key'!$I$5:$I$577,$A17,'Answer Key'!$H$5:$H$577,H$4) -> -450800 | I17: =SUMIFS('Answer Key'!$G$5:$G$577,'Answer Key'!$I$5:$I$577,$A17,'Answer Key'!$H$5:$H$577,I$4) -> -450800 | J17: =SUMIFS('Answer Key'!$G$5:$G$577,'Answer Key'!$I$5:$I$577,$A17,'Answer Key'!$H$5:$H$577,J$4) -> -487060 | ... N17: =SUMIFS('Answer Key'!$G$5:$G$577,'Answer Key'!$I$5:$I$577,$A17,'Answer Key'!$H$5:$H$577,N$4) -> -487060 | O17: =SUM(C17:N17) -> -5590900
... A44: Unidentified - Suspense | B44: Other / Suspense | C44: =SUMIFS('Answer Key'!$G$5:$G$577,'Answer Key'!$I$5:$I$577,$A44,'Answer Key'!$H$5:$H$577,C$4) -> 0 | D44: =SUMIFS('Answer Key'!$G$5:$G$577,'Answer Key'!$I$5:$I$577,$A44,'Answer Key'!$H$5:$H$577,D$4) -> 0 | E44: =SUMIFS('Answer Key'!$G$5:$G$577,'Answer Key'!$I$5:$I$577,$A44,'Answer Key'!$H$5:$H$577,E$4) -> 1250000 | F44: =SUMIFS('Answer Key'!$G$5:$G$577,'Answer Key'!$I$5:$I$577,$A44,'Answer Key'!$H$5:$H$577,F$4) -> 0 | G44: =SUMIFS('Answer Key'!$G$5:$G$577,'Answer Key'!$I$5:$I$577,$A44,'Answer Key'!$H$5:$H$577,G$4) -> 0 | H44: =SUMIFS('Answer Key'!$G$5:$G$577,'Answer Key'!$I$5:$I$577,$A44,'Answer Key'!$H$5:$H$577,H$4) -> -275000 | I44: =SUMIFS('Answer Key'!$G$5:$G$577,'Answer Key'!$I$5:$I$577,$A44,'Answer Key'!$H$5:$H$577,I$4) -> 0 | J44: =SUMIFS('Answer Key'!$G$5:$G$577,'Answer Key'!$I$5:$I$577,$A44,'Answer Key'!$H$5:$H$577,J$4) -> 0 | ... N44: =SUMIFS('Answer Key'!$G$5:$G$577,'Answer Key'!$I$5:$I$577,$A44,'Answer Key'!$H$5:$H$577,N$4) -> 0 | O44: =SUM(C44:N44) -> 3635000
A46: CASH FLOW BY CLASS
A47: Net cash - Operating | C47: =SUMIFS(C$6:C$44,$B$6:$B$44,"Operating") -> -199833.13 | D47: =SUMIFS(D$6:D$44,$B$6:$B$44,"Operating") -> 18784911 | E47: =SUMIFS(E$6:E$44,$B$6:$B$44,"Operating") -> 8008348.4 | F47: =SUMIFS(F$6:F$44,$B$6:$B$44,"Operating") -> -1657124.8 | G47: =SUMIFS(G$6:G$44,$B$6:$B$44,"Operating") -> 12479350 | H47: =SUMIFS(H$6:H$44,$B$6:$B$44,"Operating") -> 1859826.8 | I47: =SUMIFS(I$6:I$44,$B$6:$B$44,"Operating") -> 10875343 | J47: =SUMIFS(J$6:J$44,$B$6:$B$44,"Operating") -> 6470859.3 | ... O47: =SUMIFS(O$6:O$44,$B$6:$B$44,"Operating") -> 1.0650888e+08
A48: Net cash - Investing | C48: =SUMIFS(C$6:C$44,$B$6:$B$44,"Investing") -> 0 | D48: =SUMIFS(D$6:D$44,$B$6:$B$44,"Investing") -> -3500000 | E48: =SUMIFS(E$6:E$44,$B$6:$B$44,"Investing") -> 0 | F48: =SUMIFS(F$6:F$44,$B$6:$B$44,"Investing") -> 0 | G48: =SUMIFS(G$6:G$44,$B$6:$B$44,"Investing") -> 0 | H48: =SUMIFS(H$6:H$44,$B$6:$B$44,"Investing") -> -8000000 | I48: =SUMIFS(I$6:I$44,$B$6:$B$44,"Investing") -> -10000000 | J48: =SUMIFS(J$6:J$44,$B$6:$B$44,"Investing") -> 0 | ... O48: =SUMIFS(O$6:O$44,$B$6:$B$44,"Investing") -> -21500000
A49: Net cash - Financing | C49: =SUMIFS(C$6:C$44,$B$6:$B$44,"Financing") -> 0 | D49: =SUMIFS(D$6:D$44,$B$6:$B$44,"Financing") -> 4400000 | E49: =SUMIFS(E$6:E$44,$B$6:$B$44,"Financing") -> 19785000 | F49: =SUMIFS(F$6:F$44,$B$6:$B$44,"Financing") -> -1957421.9 | G49: =SUMIFS(G$6:G$44,$B$6:$B$44,"Financing") -> -1057421.9 | H49: =SUMIFS(H$6:H$44,$B$6:$B$44,"Financing") -> -1807421.9 | I49: =SUMIFS(I$6:I$44,$B$6:$B$44,"Financing") -> -1057421.9 | J49: =SUMIFS(J$6:J$44,$B$6:$B$44,"Financing") -> -2407422 | ... O49: =SUMIFS(O$6:O$44,$B$6:$B$44,"Financing") -> 10668202
A50: Net cash - Other / Suspense | C50: =SUMIFS(C$6:C$44,$B$6:$B$44,"Other / Suspense") -> 0 | D50: =SUMIFS(D$6:D$44,$B$6:$B$44,"Other / Suspense") -> 0 | E50: =SUMIFS(E$6:E$44,$B$6:$B$44,"Other / Suspense") -> 1250000 | F50: =SUMIFS(F$6:F$44,$B$6:$B$44,"Other / Suspense") -> 0 | G50: =SUMIFS(G$6:G$44,$B$6:$B$44,"Other / Suspense") -> 0 | H50: =SUMIFS(H$6:H$44,$B$6:$B$44,"Other / Suspense") -> -5275000 | I50: =SUMIFS(I$6:I$44,$B$6:$B$44,"Other / Suspense") -> 0 | J50: =SUMIFS(J$6:J$44,$B$6:$B$44,"Other / Suspense") -> 0 | ... O50: =SUMIFS(O$6:O$44,$B$6:$B$44,"Other / Suspense") -> 3635000
A51: Net cash movement for the month | C51: =SUM(C47:C50) -> -199833.13 | D51: =SUM(D47:D50) -> 19684911 | E51: =SUM(E47:E50) -> 29043348 | F51: =SUM(F47:F50) -> -3614546.8 | G51: =SUM(G47:G50) -> 11421928 | H51: =SUM(H47:H50) -> -13222595 | I51: =SUM(I47:I50) -> -182078.83 | J51: =SUM(J47:J50) -> 4063437.4 | ... O51: =SUM(O47:O50) -> 99312086
A52: Opening balance | C52: ='Bank Statement'!$H$3 -> 12500000 | D52: =C53 -> 12300167 | E52: =D53 -> 31985078 | F52: =E53 -> 61028426 | G52: =F53 -> 57413879 | H52: =G53 -> 68835808 | I52: =H53 -> 55613212 | J52: =I53 -> 55431134 | K52: =J53 -> 59494571 | ... N52: =M53 -> 96410157
A53: Closing balance | C53: =C52+C51 -> 12300167 | D53: =D52+D51 -> 31985078 | E53: =E52+E51 -> 61028426 | F53: =F52+F51 -> 57413879 | G53: =G52+G51 -> 68835808 | H53: =H52+H51 -> 55613212 | I53: =I52+I51 -> 55431134 | J53: =J52+J51 -> 59494571 | ... N53: =N52+N51 -> 1.1181209e+08
A55: Check: closing balance vs bank statement (must be zero) | N55: =ROUND(N53-'Bank Statement'!H581,2) -> 0
A57: MEMO: split of loan repayments (from Loan Schedule)
A58: Loan interest (included in repayments) | C58: =-SUMIFS('Loan Schedule'!$G$11:$G$34,'Loan Schedule'!$C$11:$C$34,2025,'Loan Schedule'!$D$11:$D$34,C$4) -> 0 | D58: =-SUMIFS('Loan Schedule'!$G$11:$G$34,'Loan Schedule'!$C$11:$C$34,2025,'Loan Schedule'!$D$11:$D$34,D$4) -> 0 | E58: =-SUMIFS('Loan Schedule'!$G$11:$G$34,'Loan Schedule'!$C$11:$C$34,2025,'Loan Schedule'!$D$11:$D$34,E$4) -> 0 | F58: =-SUMIFS('Loan Schedule'!$G$11:$G$34,'Loan Schedule'!$C$11:$C$34,2025,'Loan Schedule'!$D$11:$D$34,F$4) -> -400000 | G58: =-SUMIFS('Loan Schedule'!$G$11:$G$34,'Loan Schedule'!$C$11:$C$34,2025,'Loan Schedule'!$D$11:$D$34,G$4) -> -386851.56 | H58: =-SUMIFS('Loan Schedule'!$G$11:$G$34,'Loan Schedule'!$C$11:$C$34,2025,'Loan Schedule'!$D$11:$D$34,H$4) -> -373440.15 | I58: =-SUMIFS('Loan Schedule'!$G$11:$G$34,'Loan Schedule'!$C$11:$C$34,2025,'Loan Schedule'!$D$11:$D$34,I$4) -> -359760.52 | J58: =-SUMIFS('Loan Schedule'!$G$11:$G$34,'Loan Schedule'!$C$11:$C$34,2025,'Loan Schedule'!$D$11:$D$34,J$4) -> -345807.29 | ... N58: =-SUMIFS('Loan Schedule'!$G$11:$G$34,'Loan Schedule'!$C$11:$C$34,2025,'Loan Schedule'!$D$11:$D$34,N$4) -> -287147.36 | O58: =SUM(C58:N58) -> -3103890.7
A59: Loan principal (included in repayments) | C59: =-SUMIFS('Loan Schedule'!$H$11:$H$34,'Loan Schedule'!$C$11:$C$34,2025,'Loan Schedule'!$D$11:$D$34,C$4) -> 0 | D59: =-SUMIFS('Loan Schedule'!$H$11:$H$34,'Loan Schedule'!$C$11:$C$34,2025,'Loan Schedule'!$D$11:$D$34,D$4) -> 0 | E59: =-SUMIFS('Loan Schedule'!$H$11:$H$34,'Loan Schedule'!$C$11:$C$34,2025,'Loan Schedule'!$D$11:$D$34,E$4) -> 0 | F59: =-SUMIFS('Loan Schedule'!$H$11:$H$34,'Loan Schedule'!$C$11:$C$34,2025,'Loan Schedule'!$D$11:$D$34,F$4) -> -657421.95 | G59: =-SUMIFS('Loan Schedule'!$H$11:$H$34,'Loan Schedule'!$C$11:$C$34,2025,'Loan Schedule'!$D$11:$D$34,G$4) -> -670570.39 | H59: =-SUMIFS('Loan Schedule'!$H$11:$H$34,'Loan Schedule'!$C$11:$C$34,2025,'Loan Schedule'!$D$11:$D$34,H$4) -> -683981.8 | I59: =-SUMIFS('Loan Schedule'!$H$11:$H$34,'Loan Schedule'!$C$11:$C$34,2025,'Loan Schedule'!$D$11:$D$34,I$4) -> -697661.43 | J59: =-SUMIFS('Loan Schedule'!$H$11:$H$34,'Loan Schedule'!$C$11:$C$34,2025,'Loan Schedule'!$D$11:$D$34,J$4) -> -711614.66 | ... N59: =-SUMIFS('Loan Schedule'!$H$11:$H$34,'Loan Schedule'!$C$11:$C$34,2025,'Loan Schedule'!$D$11:$D$34,N$4) -> -770274.59 | O59: =SUM(C59:N59) -> -6412906.8
